 * Serving Flask app "flaskblog.py"
 * Environment: production
   WARNING: This is a development server. Do not use it in a production deployment.
   Use a production WSGI server instead.
 * Debug mode: off
 * Running on http://0.0.0.0:5000/ (Press CTRL+C to quit)
127.0.0.1 - - [22/Sep/2020 10:17:15] "[37mGET / HTTP/1.1[0m" 200 -
127.0.0.1 - - [22/Sep/2020 10:17:15] "[37mGET /static/img.jpg HTTP/1.1[0m" 200 -
127.0.0.1 - - [22/Sep/2020 10:17:15] "[37mGET /static/logo.png HTTP/1.1[0m" 200 -
127.0.0.1 - - [22/Sep/2020 10:17:15] "[33mGET /img.jpg HTTP/1.1[0m" 404 -
127.0.0.1 - - [22/Sep/2020 10:17:18] "[32mPOST /login HTTP/1.1[0m" 302 -
 * Serving Flask app "flaskblog.py"
 * Environment: production
   WARNING: This is a development server. Do not use it in a production deployment.
   Use a production WSGI server instead.
 * Debug mode: off
 * Running on http://0.0.0.0:5000/ (Press CTRL+C to quit)
127.0.0.1 - - [02/Nov/2020 11:41:27] "[37mGET / HTTP/1.1[0m" 200 -
127.0.0.1 - - [02/Nov/2020 11:41:30] "[37mGET /static/img.jpg HTTP/1.1[0m" 200 -
127.0.0.1 - - [02/Nov/2020 11:41:30] "[37mGET /static/logo.png HTTP/1.1[0m" 200 -
127.0.0.1 - - [02/Nov/2020 11:41:30] "[33mGET /img.jpg HTTP/1.1[0m" 404 -
[2020-11-02 11:41:51,366] ERROR in app: Exception on /login [POST]
Traceback (most recent call last):
  File "/home/thinknyx/.local/lib/python3.8/site-packages/flask/app.py", line 2447, in wsgi_app
    response = self.full_dispatch_request()
  File "/home/thinknyx/.local/lib/python3.8/site-packages/flask/app.py", line 1952, in full_dispatch_request
    rv = self.handle_user_exception(e)
  File "/home/thinknyx/.local/lib/python3.8/site-packages/flask/app.py", line 1821, in handle_user_exception
    reraise(exc_type, exc_value, tb)
  File "/home/thinknyx/.local/lib/python3.8/site-packages/flask/_compat.py", line 39, in reraise
    raise value
  File "/home/thinknyx/.local/lib/python3.8/site-packages/flask/app.py", line 1950, in full_dispatch_request
    rv = self.dispatch_request()
  File "/home/thinknyx/.local/lib/python3.8/site-packages/flask/app.py", line 1936, in dispatch_request
    return self.view_functions[rule.endpoint](**req.view_args)
  File "/home/thinknyx/AMS/ams/login/flaskblog.py", line 108, in login
    cur = mysql.connection.cursor(MySQLdb.cursors.DictCursor)
  File "/home/thinknyx/.local/lib/python3.8/site-packages/flask_mysqldb/__init__.py", line 94, in connection
    ctx.mysql_db = self.connect
  File "/home/thinknyx/.local/lib/python3.8/site-packages/flask_mysqldb/__init__.py", line 81, in connect
    return MySQLdb.connect(**kwargs)
  File "/home/thinknyx/.local/lib/python3.8/site-packages/MySQLdb/__init__.py", line 130, in Connect
    return Connection(*args, **kwargs)
  File "/home/thinknyx/.local/lib/python3.8/site-packages/MySQLdb/connections.py", line 185, in __init__
    super().__init__(*args, **kwargs2)
MySQLdb._exceptions.OperationalError: (1045, "Access denied for user 'thinknyx'@'localhost' (using password: NO)")
127.0.0.1 - - [02/Nov/2020 11:41:51] "[35m[1mPOST /login HTTP/1.1[0m" 500 -
[2020-11-02 11:41:58,106] ERROR in app: Exception on /login [POST]
Traceback (most recent call last):
  File "/home/thinknyx/.local/lib/python3.8/site-packages/flask/app.py", line 2447, in wsgi_app
    response = self.full_dispatch_request()
  File "/home/thinknyx/.local/lib/python3.8/site-packages/flask/app.py", line 1952, in full_dispatch_request
    rv = self.handle_user_exception(e)
  File "/home/thinknyx/.local/lib/python3.8/site-packages/flask/app.py", line 1821, in handle_user_exception
    reraise(exc_type, exc_value, tb)
  File "/home/thinknyx/.local/lib/python3.8/site-packages/flask/_compat.py", line 39, in reraise
    raise value
  File "/home/thinknyx/.local/lib/python3.8/site-packages/flask/app.py", line 1950, in full_dispatch_request
    rv = self.dispatch_request()
  File "/home/thinknyx/.local/lib/python3.8/site-packages/flask/app.py", line 1936, in dispatch_request
    return self.view_functions[rule.endpoint](**req.view_args)
  File "/home/thinknyx/AMS/ams/login/flaskblog.py", line 108, in login
    cur = mysql.connection.cursor(MySQLdb.cursors.DictCursor)
  File "/home/thinknyx/.local/lib/python3.8/site-packages/flask_mysqldb/__init__.py", line 94, in connection
    ctx.mysql_db = self.connect
  File "/home/thinknyx/.local/lib/python3.8/site-packages/flask_mysqldb/__init__.py", line 81, in connect
    return MySQLdb.connect(**kwargs)
  File "/home/thinknyx/.local/lib/python3.8/site-packages/MySQLdb/__init__.py", line 130, in Connect
    return Connection(*args, **kwargs)
  File "/home/thinknyx/.local/lib/python3.8/site-packages/MySQLdb/connections.py", line 185, in __init__
    super().__init__(*args, **kwargs2)
MySQLdb._exceptions.OperationalError: (1045, "Access denied for user 'thinknyx'@'localhost' (using password: NO)")
127.0.0.1 - - [02/Nov/2020 11:41:58] "[35m[1mPOST /login HTTP/1.1[0m" 500 -
 * Serving Flask app "flaskblog.py" (lazy loading)
 * Environment: development
 * Debug mode: on
 * Running on http://0.0.0.0:5000/ (Press CTRL+C to quit)
 * Restarting with stat
 * Debugger is active!
 * Debugger PIN: 164-237-922
127.0.0.1 - - [02/Nov/2020 11:54:23] "[32mPOST /login HTTP/1.1[0m" 302 -
 * Serving Flask app "flaskblog.py" (lazy loading)
 * Environment: development
 * Debug mode: on
 * Running on http://0.0.0.0:5000/ (Press CTRL+C to quit)
 * Restarting with stat
 * Debugger is active!
 * Debugger PIN: 896-609-507
127.0.0.1 - - [03/Nov/2020 22:08:16] "[37mGET / HTTP/1.1[0m" 200 -
127.0.0.1 - - [03/Nov/2020 22:08:16] "[33mGET /img.jpg HTTP/1.1[0m" 404 -
127.0.0.1 - - [03/Nov/2020 22:08:17] "[33mGET /favicon.ico HTTP/1.1[0m" 404 -
127.0.0.1 - - [03/Nov/2020 22:08:30] "[32mPOST /login HTTP/1.1[0m" 302 -
 * Serving Flask app "flaskblog.py" (lazy loading)
 * Environment: development
 * Debug mode: on
 * Running on http://0.0.0.0:5000/ (Press CTRL+C to quit)
 * Restarting with stat
 * Debugger is active!
 * Debugger PIN: 113-769-593
127.0.0.1 - - [04/Nov/2020 19:51:44] "[37mGET / HTTP/1.1[0m" 200 -
127.0.0.1 - - [04/Nov/2020 19:51:45] "[36mGET /static/img.jpg HTTP/1.1[0m" 304 -
127.0.0.1 - - [04/Nov/2020 19:51:45] "[36mGET /static/logo.png HTTP/1.1[0m" 304 -
127.0.0.1 - - [04/Nov/2020 19:51:45] "[33mGET /img.jpg HTTP/1.1[0m" 404 -
127.0.0.1 - - [04/Nov/2020 19:51:45] "[33mGET /favicon.ico HTTP/1.1[0m" 404 -
127.0.0.1 - - [04/Nov/2020 19:51:47] "[37mGET / HTTP/1.1[0m" 200 -
127.0.0.1 - - [04/Nov/2020 19:51:48] "[33mGET /img.jpg HTTP/1.1[0m" 404 -
127.0.0.1 - - [04/Nov/2020 20:09:34] "[37mGET / HTTP/1.1[0m" 200 -
127.0.0.1 - - [04/Nov/2020 20:09:34] "[33mGET /img.jpg HTTP/1.1[0m" 404 -
127.0.0.1 - - [04/Nov/2020 20:09:44] "[32mPOST /login HTTP/1.1[0m" 302 -
 * Serving Flask app "flaskblog.py" (lazy loading)
 * Environment: development
 * Debug mode: on
 * Running on http://0.0.0.0:5000/ (Press CTRL+C to quit)
 * Restarting with stat
 * Debugger is active!
 * Debugger PIN: 274-479-314
 * Serving Flask app "flaskblog.py" (lazy loading)
 * Environment: development
 * Debug mode: on
Traceback (most recent call last):
  File "/home/thinknyx/.local/bin/flask", line 8, in <module>
    sys.exit(main())
  File "/home/thinknyx/.local/lib/python3.8/site-packages/flask/cli.py", line 967, in main
    cli.main(args=sys.argv[1:], prog_name="python -m flask" if as_module else None)
  File "/home/thinknyx/.local/lib/python3.8/site-packages/flask/cli.py", line 586, in main
    return super(FlaskGroup, self).main(*args, **kwargs)
  File "/usr/lib/python3/dist-packages/click/core.py", line 717, in main
    rv = self.invoke(ctx)
  File "/usr/lib/python3/dist-packages/click/core.py", line 1137, in invoke
    return _process_result(sub_ctx.command.invoke(sub_ctx))
  File "/usr/lib/python3/dist-packages/click/core.py", line 956, in invoke
    return ctx.invoke(self.callback, **ctx.params)
  File "/usr/lib/python3/dist-packages/click/core.py", line 555, in invoke
    return callback(*args, **kwargs)
  File "/usr/lib/python3/dist-packages/click/decorators.py", line 64, in new_func
    return ctx.invoke(f, obj, *args, **kwargs)
  File "/usr/lib/python3/dist-packages/click/core.py", line 555, in invoke
    return callback(*args, **kwargs)
  File "/home/thinknyx/.local/lib/python3.8/site-packages/flask/cli.py", line 852, in run_command
    run_simple(
  File "/home/thinknyx/.local/lib/python3.8/site-packages/werkzeug/serving.py", line 1030, in run_simple
    s.bind(server_address)
OSError: [Errno 98] Address already in use
 * Serving Flask app "flaskblog.py" (lazy loading)
 * Environment: development
 * Debug mode: on
Traceback (most recent call last):
  File "/home/thinknyx/.local/bin/flask", line 8, in <module>
    sys.exit(main())
  File "/home/thinknyx/.local/lib/python3.8/site-packages/flask/cli.py", line 967, in main
    cli.main(args=sys.argv[1:], prog_name="python -m flask" if as_module else None)
  File "/home/thinknyx/.local/lib/python3.8/site-packages/flask/cli.py", line 586, in main
    return super(FlaskGroup, self).main(*args, **kwargs)
  File "/usr/lib/python3/dist-packages/click/core.py", line 717, in main
    rv = self.invoke(ctx)
  File "/usr/lib/python3/dist-packages/click/core.py", line 1137, in invoke
    return _process_result(sub_ctx.command.invoke(sub_ctx))
  File "/usr/lib/python3/dist-packages/click/core.py", line 956, in invoke
    return ctx.invoke(self.callback, **ctx.params)
  File "/usr/lib/python3/dist-packages/click/core.py", line 555, in invoke
    return callback(*args, **kwargs)
  File "/usr/lib/python3/dist-packages/click/decorators.py", line 64, in new_func
    return ctx.invoke(f, obj, *args, **kwargs)
  File "/usr/lib/python3/dist-packages/click/core.py", line 555, in invoke
    return callback(*args, **kwargs)
  File "/home/thinknyx/.local/lib/python3.8/site-packages/flask/cli.py", line 852, in run_command
    run_simple(
  File "/home/thinknyx/.local/lib/python3.8/site-packages/werkzeug/serving.py", line 1030, in run_simple
    s.bind(server_address)
OSError: [Errno 98] Address already in use
 * Serving Flask app "flaskblog.py" (lazy loading)
 * Environment: development
 * Debug mode: on
Traceback (most recent call last):
  File "/home/thinknyx/.local/bin/flask", line 8, in <module>
    sys.exit(main())
  File "/home/thinknyx/.local/lib/python3.8/site-packages/flask/cli.py", line 967, in main
    cli.main(args=sys.argv[1:], prog_name="python -m flask" if as_module else None)
  File "/home/thinknyx/.local/lib/python3.8/site-packages/flask/cli.py", line 586, in main
    return super(FlaskGroup, self).main(*args, **kwargs)
  File "/usr/lib/python3/dist-packages/click/core.py", line 717, in main
    rv = self.invoke(ctx)
  File "/usr/lib/python3/dist-packages/click/core.py", line 1137, in invoke
    return _process_result(sub_ctx.command.invoke(sub_ctx))
  File "/usr/lib/python3/dist-packages/click/core.py", line 956, in invoke
    return ctx.invoke(self.callback, **ctx.params)
  File "/usr/lib/python3/dist-packages/click/core.py", line 555, in invoke
    return callback(*args, **kwargs)
  File "/usr/lib/python3/dist-packages/click/decorators.py", line 64, in new_func
    return ctx.invoke(f, obj, *args, **kwargs)
  File "/usr/lib/python3/dist-packages/click/core.py", line 555, in invoke
    return callback(*args, **kwargs)
  File "/home/thinknyx/.local/lib/python3.8/site-packages/flask/cli.py", line 852, in run_command
    run_simple(
  File "/home/thinknyx/.local/lib/python3.8/site-packages/werkzeug/serving.py", line 1030, in run_simple
    s.bind(server_address)
OSError: [Errno 98] Address already in use
 * Serving Flask app "flaskblog.py" (lazy loading)
 * Environment: development
 * Debug mode: on
Traceback (most recent call last):
  File "/home/thinknyx/.local/bin/flask", line 8, in <module>
    sys.exit(main())
  File "/home/thinknyx/.local/lib/python3.8/site-packages/flask/cli.py", line 967, in main
    cli.main(args=sys.argv[1:], prog_name="python -m flask" if as_module else None)
  File "/home/thinknyx/.local/lib/python3.8/site-packages/flask/cli.py", line 586, in main
    return super(FlaskGroup, self).main(*args, **kwargs)
  File "/usr/lib/python3/dist-packages/click/core.py", line 717, in main
    rv = self.invoke(ctx)
  File "/usr/lib/python3/dist-packages/click/core.py", line 1137, in invoke
    return _process_result(sub_ctx.command.invoke(sub_ctx))
  File "/usr/lib/python3/dist-packages/click/core.py", line 956, in invoke
    return ctx.invoke(self.callback, **ctx.params)
  File "/usr/lib/python3/dist-packages/click/core.py", line 555, in invoke
    return callback(*args, **kwargs)
  File "/usr/lib/python3/dist-packages/click/decorators.py", line 64, in new_func
    return ctx.invoke(f, obj, *args, **kwargs)
  File "/usr/lib/python3/dist-packages/click/core.py", line 555, in invoke
    return callback(*args, **kwargs)
  File "/home/thinknyx/.local/lib/python3.8/site-packages/flask/cli.py", line 852, in run_command
    run_simple(
  File "/home/thinknyx/.local/lib/python3.8/site-packages/werkzeug/serving.py", line 1030, in run_simple
    s.bind(server_address)
OSError: [Errno 98] Address already in use
 * Serving Flask app "flaskblog.py" (lazy loading)
 * Environment: development
 * Debug mode: on
Traceback (most recent call last):
  File "/home/thinknyx/.local/bin/flask", line 8, in <module>
    sys.exit(main())
  File "/home/thinknyx/.local/lib/python3.8/site-packages/flask/cli.py", line 967, in main
    cli.main(args=sys.argv[1:], prog_name="python -m flask" if as_module else None)
  File "/home/thinknyx/.local/lib/python3.8/site-packages/flask/cli.py", line 586, in main
    return super(FlaskGroup, self).main(*args, **kwargs)
  File "/usr/lib/python3/dist-packages/click/core.py", line 717, in main
    rv = self.invoke(ctx)
  File "/usr/lib/python3/dist-packages/click/core.py", line 1137, in invoke
    return _process_result(sub_ctx.command.invoke(sub_ctx))
  File "/usr/lib/python3/dist-packages/click/core.py", line 956, in invoke
    return ctx.invoke(self.callback, **ctx.params)
  File "/usr/lib/python3/dist-packages/click/core.py", line 555, in invoke
    return callback(*args, **kwargs)
  File "/usr/lib/python3/dist-packages/click/decorators.py", line 64, in new_func
    return ctx.invoke(f, obj, *args, **kwargs)
  File "/usr/lib/python3/dist-packages/click/core.py", line 555, in invoke
    return callback(*args, **kwargs)
  File "/home/thinknyx/.local/lib/python3.8/site-packages/flask/cli.py", line 852, in run_command
    run_simple(
  File "/home/thinknyx/.local/lib/python3.8/site-packages/werkzeug/serving.py", line 1030, in run_simple
    s.bind(server_address)
OSError: [Errno 98] Address already in use
 * Serving Flask app "flaskblog.py" (lazy loading)
 * Environment: development
 * Debug mode: on
 * Running on http://0.0.0.0:5000/ (Press CTRL+C to quit)
 * Restarting with stat
 * Debugger is active!
 * Debugger PIN: 274-479-314
 * Detected change in '/usr/lib/python3/dist-packages/cryptography/hazmat/bindings/_constant_time.abi3.so', reloading
 * Restarting with stat
 * Debugger is active!
 * Debugger PIN: 274-479-314
